Workbook

Sheet CRFDraft
A1: DraftName | B1: DeleteExisting | C1: ProjectName | D1: ProjectType | E1: PrimaryFormOID | F1: DefaultMatrixOID | G1: ConfirmationMessage | H1: SignaturePrompt | I1: LabStandardGroup | J1: ReferenceLabs | K1: AlertLabs | L1: SyncOIDProject | M1: SyncOIDDraft | N1: SyncOIDProjectType | O1: SyncOIDOriginIsVersion | P1: SourceUrlId
A2: STUDY-ABC-001 | B2: FALSE | C2: STUDY-ABC-001 | D2: Project | E2: SUBJECT | F2: PRIMARY | G2: Your form has been submitted. Thank you. | H2: As PI, I understand and certify that the information submitted within the application is true, complete, and accurate to the best of my knowledge. | N2: Project | O2: FALSE | P2: clinfocus-innovate | GR2: =IF(LEN(Forms!$A2)>0,Forms!$A2,"") -> SUBJECT
GR3: =IF(LEN(Forms!$A3)>0,Forms!$A3,"") -> SV
GR4: =IF(LEN(Forms!$A4)>0,Forms!$A4,"") -> IC
GR5: =IF(LEN(Forms!$A5)>0,Forms!$A5,"") -> DM
GR6: =IF(LEN(Forms!$A6)>0,Forms!$A6,"") -> CONTD
GR7: =IF(LEN(Forms!$A7)>0,Forms!$A7,"") -> IE
GR8: =IF(LEN(Forms!$A8)>0,Forms!$A8,"")
GR9: =IF(LEN(Forms!$A9)>0,Forms!$A9,"")
GR10: =IF(LEN(Forms!$A10)>0,Forms!$A10,"")
GR11: =IF(LEN(Forms!$A11)>0,Forms!$A11,"")
GR12: =IF(LEN(Forms!$A12)>0,Forms!$A12,"")
GR13: =IF(LEN(Forms!$A13)>0,Forms!$A13,"")
GR14: =IF(LEN(Forms!$A14)>0,Forms!$A14,"")
... GR27: =IF(LEN(Forms!$A27)>0,Forms!$A27,"")

Sheet Forms
A1: OID | B1: Ordinal | C1: DraftFormName | D1: DraftFormActive | E1: HelpText | F1: IsTemplate | G1: IsSignatureRequired | H1: IsEproForm | I1: ViewRestrictions | J1: EntryRestrictions | K1: LogDirection | L1: DDEOption | M1: ConfirmationStyle | N1: LinkFolderOID | O1: LinkFormOID | P1: DownloadedFromObjectId | Q1: SourceObjectId | R1: SourceUrlId
A2: SUBJECT | B2: 1 | C2: Subject ID | D2: TRUE | F2: FALSE | G2: TRUE | H2: FALSE | J2: Clinical Research Associate,Data Manager,Investigator,Safety | L2: MustNotDDE | P2: 8673 | Q2: 8114 | GR2: =IF(LEN(Folders!$A2)>0,Folders!$A2,"") -> SCRN
A3: SV | B3: 2 | C3: Visit Date | D3: TRUE | F3: FALSE | G3: TRUE | H3: FALSE | J3: Clinical Research Associate,Data Manager,Investigator,Safety | L3: MustNotDDE | P3: 8674 | Q3: 8115 | GR3: =IF(LEN(Folders!$A3)>0,Folders!$A3,"") -> BASE
A4: IC | B4: 4 | C4: Informed Consent | D4: TRUE | F4: FALSE | G4: TRUE | H4: FALSE | J4: Clinical Research Associate,Data Manager,Investigator,Safety | L4: MustNotDDE | P4: 8675 | Q4: 8116 | GR4: =IF(LEN(Folders!$A4)>0,Folders!$A4,"")
A5: DM | B5: 6 | C5: Demographics | D5: TRUE | F5: FALSE | G5: TRUE | H5: FALSE | J5: Clinical Research Associate,Data Manager,Investigator,Safety | L5: MustNotDDE | P5: 8676 | Q5: 8118 | GR5: =IF(LEN(Folders!$A5)>0,Folders!$A5,"")
A6: CONTD | B6: 40 | C6: Subject Continuation | D6: TRUE | F6: FALSE | G6: TRUE | H6: FALSE | J6: Clinical Research Associate,Data Manager,Investigator,Safety | L6: MustNotDDE | P6: 8677 | Q6: 8151 | GR6: =IF(LEN(Folders!$A6)>0,Folders!$A6,"")
A7: IE | B7: 45 | C7: Eligibility | D7: TRUE | F7: FALSE | G7: TRUE | H7: FALSE | J7: Clinical Research Associate,Data Manager,Investigator,Safety | K7: Landscape | L7: MustNotDDE | M7: NoLink | P7: 8678 | Q7: 8117 | GR7: =IF(LEN(Folders!$A7)>0,Folders!$A7,"")
GR8: =IF(LEN(Folders!$A8)>0,Folders!$A8,"")
GR9: =IF(LEN(Folders!$A9)>0,Folders!$A9,"")
GR10: =IF(LEN(Folders!$A10)>0,Folders!$A10,"")
GR11: =IF(LEN(Folders!$A11)>0,Folders!$A11,"")
GR12: =IF(LEN(Folders!$A12)>0,Folders!$A12,"")
GR13: =IF(LEN(Folders!$A13)>0,Folders!$A13,"")
GR14: =IF(LEN(Folders!$A14)>0,Folders!$A14,"")
GR15: =IF(LEN(Folders!$A15)>0,Folders!$A15,"")
GR16: =IF(LEN(Folders!$A16)>0,Folders!$A16,"")
GR17: =IF(LEN(Folders!$A17)>0,Folders!$A17,"")
GR18: =IF(LEN(Folders!$A18)>0,Folders!$A18,"")
GR19: =IF(LEN(Folders!$A19)>0,Folders!$A19,"")
... GR27: =IF(LEN(Folders!$A27)>0,Folders!$A27,"")

Sheet Fields
A1: FormOID | B1: FieldOID | C1: Ordinal | D1: DraftFieldNumber | E1: DraftFieldName | F1: DraftFieldActive | G1: VariableOID | H1: DataFormat | I1: DataDictionaryName | J1: UnitDictionaryName | K1: CodingDictionary | L1: ControlType | M1: AcceptableFileExtensions | N1: IndentLevel | O1: PreText | P1: FixedUnit | Q1: HeaderText | R1: HelpText | S1: SourceDocument | T1: IsLog | U1: DefaultValue | V1: SASLabel | W1: SASFormat | X1: EproFormat | Y1: IsRequired | Z1: QueryFutureDate | AA1: IsVisible | AB1: IsTranslationRequired | AC1: AnalyteName | AD1: IsClinicalSignificance | AE1: QueryNonConformance | AF1: OtherVisits | AG1: CanSetRecordDate | AH1: CanSetDataPageDate | AI1: CanSetInstanceDate | AJ1: CanSetSubjectDate | AK1: DoesNotBreakSignature | AL1: LowerRange | AM1: UpperRange | AN1: NCLowerRange | AO1: NCUpperRange | AP1: ViewRestrictions | AQ1: EntryRestrictions | AR1: ReviewGroups | AS1: IsVisualVerify | AT1: FDownloadedFromObjectId | AU1: FSourceObjectId | AV1: VDownloadedFromObjectId | AW1: VSourceObjectId | AX1: FSourceUrlId | AY1: VSourceUrlId | AZ1: AnalyteName_ValCol
A2: SUBJECT | B2: SUB_HEADER | C2: 1 | E2: SUB_HEADER | F2: TRUE | L2: Text | N2: 0 | O2: Kindly save this form to create a subject. | S2: FALSE | T2: FALSE | Y2: FALSE | Z2: FALSE | AA2: TRUE | AB2: FALSE | AD2: FALSE | AE2: FALSE | AF2: FALSE | AG2: FALSE | AH2: FALSE | AI2: FALSE | AJ2: FALSE | AK2: FALSE | AR2: Data Management | AS2: FALSE | AT2: 84039 | AU2: 78663 | AZ2: Partial Thromboplastin Time (PTT) | GR2: =IF(LEN(UnitDictionaries!$A2)>0,UnitDictionaries!$A2,"") | GS2: =IF(LEN(Forms!$A2)>0,Forms!$A2,"") -> SUBJECT | GT2: =IF(LEN(DataDictionaries!$A2)>0,DataDictionaries!$A2,"") -> YesNo
A3: SUBJECT | B3: SUBJID | C3: 2 | E3: SUBJID | F3: TRUE | G3: SUBJID | H3: $20 | L3: Text | N3: 0 | O3: Subject ID (derived) | S3: FALSE | T3: FALSE | V3: Subject ID | Y3: FALSE | Z3: FALSE | AA3: TRUE | AB3: FALSE | AD3: FALSE | AE3: FALSE | AF3: FALSE | AG3: FALSE | AH3: FALSE | AI3: FALSE | AJ3: FALSE | AK3: FALSE | AQ3: Batch Upload,Clinical Research Associate,Clinical Research Coordinator,Coder,Coder Import Role,Data Manager,Investigator,IxRS - Clinical Research Coordinator,IxRS - Investigator,Medical Monitor,Monitoring Data Manager,OL Role,Outputs Locked,Outputs Standard,Power User,Rave Imaging Integration,Rave Web Services (RWS),Read Only,Read Only - All Sites,Safety | AS3: FALSE | AT3: 84059 | AU3: 78664 | AV3: 77177 | AW3: 72269 | AZ3: Alanine aminotransferase (ALT) | GR3: =IF(LEN(UnitDictionaries!$A3)>0,UnitDictionaries!$A3,"") | GS3: =IF(LEN(Forms!$A3)>0,Forms!$A3,"") -> SV | GT3: =IF(LEN(DataDictionaries!$A3)>0,DataDictionaries!$A3,"") -> ICPROT
A4: SUBJECT | B4: SUBMDTM | C4: 3 | E4: SUBMDTM | F4: TRUE | G4: SUBMDTM | H4: dd MMM yyyy HH:nn:ss | L4: DateTime | N4: 0 | O4: Hidden Date Submitted | S4: FALSE | T4: FALSE | V4: Hidden Date Submitted | Y4: FALSE | Z4: TRUE | AA4: TRUE | AB4: FALSE | AD4: FALSE | AE4: TRUE | AF4: FALSE | AG4: FALSE | AH4: FALSE | AI4: FALSE | AJ4: FALSE | AK4: TRUE | AP4: Coder Import Role,Batch Upload,Rave Imaging Integration,OL Role,Clinical Research Associate,Clinical Research Coordinator,Coder,Data Manager,Investigator,IxRS - Clinical Research Coordinator,IxRS - Investigator,Monitoring Data Manager,Outputs Locked,Outputs Standard,Rave Web Services (RWS),Read Only,Read Only - All Sites,Safety,Medical Monitor | AQ4: Batch Upload,Clinical Research Associate,Clinical Research Coordinator,Coder,Coder Import Role,Data Manager,Investigator,IxRS - Clinical Research Coordinator,IxRS - Investigator,Medical Monitor,Monitoring Data Manager,OL Role,Outputs Locked,Outputs Standard,Power User,Rave Imaging Integration,Rave Web Services (RWS),Read Only,Read Only - All Sites,Safety | AS4: FALSE | AT4: 84061 | AU4: 78665 | AV4: 77179 | AW4: 72270 | AZ4: Albumin (ALB) | GR4: =IF(LEN(UnitDictionaries!$A4)>0,UnitDictionaries!$A4,"") | GS4: =IF(LEN(Forms!$A4)>0,Forms!$A4,"") -> IC | GT4: =IF(LEN(DataDictionaries!$A4)>0,DataDictionaries!$A4,"") -> CBP
A5: SV | B5: SVOCCUR | C5: 1 | E5: SVOCCUR | F5: TRUE | G5: SVOCCUR | H5: $1 | I5: YesNo | L5: RadioButton (Vertical) | N5: 0 | O5: Was this visit performed? | S5: FALSE | T5: FALSE | V5: Was visit performed | Y5: TRUE | Z5: FALSE | AA5: TRUE | AB5: FALSE | AD5: FALSE | AE5: FALSE | AF5: FALSE | AG5: FALSE | AH5: FALSE | AI5: FALSE | AJ5: FALSE | AK5: FALSE | AR5: Data Management | AS5: FALSE | AT5: 84043 | AU5: 78592 | AV5: 77161 | AW5: 72271 | AZ5: Alkaline Phosphatase (ALP) | GR5: =IF(LEN(UnitDictionaries!$A5)>0,UnitDictionaries!$A5,"") | GS5: =IF(LEN(Forms!$A5)>0,Forms!$A5,"") -> DM | GT5: =IF(LEN(DataDictionaries!$A5)>0,DataDictionaries!$A5,"") -> ETHNICITY
A6: SV | B6: SVREASND | C6: 2 | E6: SVREASND | F6: TRUE | G6: SVREASND | H6: $200 | L6: LongText | N6: 0 | O6: If no, provide reason | S6: FALSE | T6: FALSE | V6: Reason not performed | Y6: TRUE | Z6: FALSE | AA6: FALSE | AB6: FALSE | AD6: FALSE | AE6: FALSE | AF6: FALSE | AG6: FALSE | AH6: FALSE | AI6: FALSE | AJ6: FALSE | AK6: FALSE | AR6: Data Management | AS6: FALSE | AT6: 84050 | AU6: 78593 | AV6: 77168 | AW6: 72272 | AZ6: Creatinine Kinase (CK) | GR6: =IF(LEN(UnitDictionaries!$A6)>0,UnitDictionaries!$A6,"") | GS6: =IF(LEN(Forms!$A6)>0,Forms!$A6,"") -> CONTD | GT6: =IF(LEN(DataDictionaries!$A6)>0,DataDictionaries!$A6,"") -> RACE
A7: SV | B7: SVDAT | C7: 3 | E7: SVDAT | F7: TRUE | G7: SVDAT | H7: dd MMM yyyy | L7: DateTime | N7: 0 | O7: Visit date | S7: FALSE | T7: FALSE | V7: Visit date | Y7: TRUE | Z7: TRUE | AA7: FALSE | AB7: FALSE | AD7: FALSE | AE7: TRUE | AF7: FALSE | AG7: FALSE | AH7: FALSE | AI7: TRUE | AJ7: FALSE | AK7: FALSE | AR7: Data Management | AS7: FALSE | AT7: 84049 | AU7: 78591 | AV7: 77167 | AW7: 72273 | AZ7: Chloride (CL) | GR7: =IF(LEN(UnitDictionaries!$A7)>0,UnitDictionaries!$A7,"") | GS7: =IF(LEN(Forms!$A7)>0,Forms!$A7,"") -> IE | GT7: =IF(LEN(DataDictionaries!$A7)>0,DataDictionaries!$A7,"") -> SEX
A8: IC | B8: ICYN | C8: 1 | E8: ICYN | F8: TRUE | G8: ICYN | H8: $1 | I8: YesNo | L8: RadioButton (Vertical) | N8: 0 | O8: Was informed consent obtained? | S8: FALSE | T8: FALSE | V8: Was informed consent obtained | Y8: TRUE | Z8: FALSE | AA8: TRUE | AB8: FALSE | AD8: FALSE | AE8: FALSE | AF8: FALSE | AG8: FALSE | AH8: FALSE | AI8: FALSE | AJ8: FALSE | AK8: FALSE | AR8: Data Management | AS8: FALSE | AT8: 84042 | AU8: 78589 | AV8: 77160 | AW8: 72278 | AZ8: Carbon-dioxide (CO2) | GR8: =IF(LEN(UnitDictionaries!$A8)>0,UnitDictionaries!$A8,"") | GS8: =IF(LEN(Forms!$A8)>0,Forms!$A8,"") | GT8: =IF(LEN(DataDictionaries!$A8)>0,DataDictionaries!$A8,"") -> Criterion Number
A9: IC | B9: RFICDAT | C9: 2 | E9: RFICDAT | F9: TRUE | G9: RFICDAT | H9: dd MMM yyyy | L9: DateTime | N9: 0 | O9: Informed Consent Date | S9: FALSE | T9: FALSE | V9: Informed Consent Date | Y9: TRUE | Z9: TRUE | AA9: FALSE | AB9: FALSE | AD9: FALSE | AE9: TRUE | AF9: FALSE | AG9: FALSE | AH9: FALSE | AI9: FALSE | AJ9: FALSE | AK9: FALSE | AR9: Data Management | AS9: FALSE | AT9: 84048 | AU9: 78590 | AV9: 77166 | AW9: 72279 | AZ9: Creatinine (CREAT) | GR9: =IF(LEN(UnitDictionaries!$A9)>0,UnitDictionaries!$A9,"") | GS9: =IF(LEN(Forms!$A9)>0,Forms!$A9,"") | GT9: =IF(LEN(DataDictionaries!$A9)>0,DataDictionaries!$A9,"")
A10: IC | B10: ICTIM | C10: 3 | E10: ICTIM | F10: TRUE | G10: ICTIM | H10: HH:nn | L10: DateTime | N10: 0 | O10: Time informed consent signed (HH:MM) | S10: FALSE | T10: FALSE | V10: Time informed consent signed (HH:MM) | Y10: TRUE | Z10: FALSE | AA10: FALSE | AB10: FALSE | AD10: FALSE | AE10: FALSE | AF10: FALSE | AG10: FALSE | AH10: FALSE | AI10: FALSE | AJ10: FALSE | AK10: FALSE | AR10: Data Management | AS10: FALSE | AT10: 84047 | AU10: 78588 | AV10: 77165 | AW10: 72280 | AZ10: Eosinophils Absolute (EOS_ABS) | GR10: =IF(LEN(UnitDictionaries!$A10)>0,UnitDictionaries!$A10,"") | GS10: =IF(LEN(Forms!$A10)>0,Forms!$A10,"") | GT10: =IF(LEN(DataDictionaries!$A10)>0,DataDictionaries!$A10,"")
A11: IC | B11: ICPROT | C11: 4 | E11: ICPROT | F11: TRUE | G11: ICPROT | H11: $2 | I11: ICPROT | L11: DropDownList | N11: 0 | O11: Protocol Version | S11: FALSE | T11: FALSE | V11: Protocol Version | Y11: TRUE | Z11: FALSE | AA11: FALSE | AB11: FALSE | AD11: FALSE | AE11: FALSE | AF11: FALSE | AG11: FALSE | AH11: FALSE | AI11: FALSE | AJ11: FALSE | AK11: FALSE | AR11: Data Management | AS11: FALSE | AT11: 84046 | AU11: 78587 | AV11: 77164 | AW11: 72281 | AZ11: Gamma-glutamyl Transferase (GGT) | GR11: =IF(LEN(UnitDictionaries!$A11)>0,UnitDictionaries!$A11,"") | GS11: =IF(LEN(Forms!$A11)>0,Forms!$A11,"") | GT11: =IF(LEN(DataDictionaries!$A11)>0,DataDictionaries!$A11,"")
A12: DM | B12: BRTHDAT | C12: 1 | E12: BRTHDAT | F12: TRUE | G12: BRTHDAT | H12: yyyy | L12: DateTime | N12: 0 | O12: Year of Birth | S12: FALSE | T12: FALSE | V12: Year of Birth | Y12: TRUE | Z12: TRUE | AA12: TRUE | AB12: FALSE | AD12: FALSE | AE12: TRUE | AF12: FALSE | AG12: FALSE | AH12: FALSE | AI12: FALSE | AJ12: FALSE | AK12: FALSE | AS12: FALSE | AT12: 84051 | AU12: 78595 | AV12: 77169 | AW12: 72286 | AZ12: Glucose (GLUC) | GR12: =IF(LEN(UnitDictionaries!$A12)>0,UnitDictionaries!$A12,"") | GS12: =IF(LEN(Forms!$A12)>0,Forms!$A12,"") | GT12: =IF(LEN(DataDictionaries!$A12)>0,DataDictionaries!$A12,"")
A13: DM | B13: AGE | C13: 2 | E13: AGE | F13: TRUE | G13: AGE | H13: 3 | L13: Text | N13: 0 | O13: Age | P13: Years | S13: FALSE | T13: FALSE | V13: Age | Y13: FALSE | Z13: FALSE | AA13: TRUE | AB13: FALSE | AD13: FALSE | AE13: FALSE | AF13: FALSE | AG13: FALSE | AH13: FALSE | AI13: FALSE | AJ13: FALSE | AK13: FALSE | AS13: FALSE | AT13: 84060 | AU13: 78594 | AV13: 77178 | AW13: 72287 | AZ13: Hematocrit (HCT) | GR13: =IF(LEN(UnitDictionaries!$A13)>0,UnitDictionaries!$A13,"") | GS13: =IF(LEN(Forms!$A13)>0,Forms!$A13,"") | GT13: =IF(LEN(DataDictionaries!$A13)>0,DataDictionaries!$A13,"")
A14: DM | B14: SEX | C14: 3 | E14: SEX | F14: TRUE | G14: SEX | H14: $1 | I14: SEX | L14: RadioButton (Vertical) | N14: 0 | O14: Sex at birth | S14: FALSE | T14: FALSE | V14: Sex at birth | Y14: TRUE | Z14: FALSE | AA14: TRUE | AB14: FALSE | AD14: FALSE | AE14: FALSE | AF14: FALSE | AG14: FALSE | AH14: FALSE | AI14: FALSE | AJ14: FALSE | AK14: FALSE | AS14: FALSE | AT14: 84058 | AU14: 78603 | AV14: 77176 | AW14: 72288 | AZ14: Hemoglobin (HGB) | GR14: =IF(LEN(UnitDictionaries!$A14)>0,UnitDictionaries!$A14,"") | GS14: =IF(LEN(Forms!$A14)>0,Forms!$A14,"") | GT14: =IF(LEN(DataDictionaries!$A14)>0,DataDictionaries!$A14,"")
A15: DM | B15: CBPYN | C15: 4 | E15: CBPYN | F15: TRUE | G15: CBPYN | H15: $1 | I15: YesNo | L15: RadioButton (Vertical) | N15: 0 | O15: If Female, is subject of childbearing potential? | S15: FALSE | T15: FALSE | V15: Subject of childbearing potential | Y15: TRUE | Z15: FALSE | AA15: FALSE | AB15: FALSE | AD15: FALSE | AE15: FALSE | AF15: FALSE | AG15: FALSE | AH15: FALSE | AI15: FALSE | AJ15: FALSE | AK15: FALSE | AS15: FALSE | AT15: 84044 | AU15: 78596 | AV15: 77162 | AW15: 72289 | AZ15: Aspartate transaminase (AST) | GR15: =IF(LEN(UnitDictionaries!$A15)>0,UnitDictionaries!$A15,"") | GS15: =IF(LEN(Forms!$A15)>0,Forms!$A15,"") | GT15: =IF(LEN(DataDictionaries!$A15)>0,DataDictionaries!$A15,"")
A16: DM | B16: CBRSN | C16: 5 | E16: CBRSN | F16: TRUE | G16: CBRSN | H16: $1 | I16: CBP | L16: DropDownList | N16: 0 | O16: If no, provide reason | S16: FALSE | T16: FALSE | V16: Specify reason | Y16: TRUE | Z16: FALSE | AA16: FALSE | AB16: FALSE | AD16: FALSE | AE16: FALSE | AF16: FALSE | AG16: FALSE | AH16: FALSE | AI16: FALSE | AJ16: FALSE | AK16: FALSE | AS16: FALSE | AT16: 84052 | AU16: 78597 | AV16: 77170 | AW16: 72290 | AZ16: Basophils (Absolute) | GR16: =IF(LEN(UnitDictionaries!$A16)>0,UnitDictionaries!$A16,"") | GS16: =IF(LEN(Forms!$A16)>0,Forms!$A16,"") | GT16: =IF(LEN(DataDictionaries!$A16)>0,DataDictionaries!$A16,"")
A17: DM | B17: CBRSN1DAT | C17: 6 | E17: CBRSN1DAT | F17: TRUE | G17: CBRSN1DAT | H17: dd- MMM- yyyy | L17: DateTime | N17: 0 | O17: If Permanent sterilization or Postmenopausal, provide date | S17: FALSE | T17: FALSE | V17: Date if surgically sterile or post menopausal | Y17: TRUE | Z17: TRUE | AA17: FALSE | AB17: FALSE | AD17: FALSE | AE17: TRUE | AF17: FALSE | AG17: FALSE | AH17: FALSE | AI17: FALSE | AJ17: FALSE | AK17: FALSE | AS17: FALSE | AT17: 84053 | AU17: 78598 | AV17: 77171 | AW17: 72291 | AZ17: Bicarbonate (BICARB) | GR17: =IF(LEN(UnitDictionaries!$A17)>0,UnitDictionaries!$A17,"") | GS17: =IF(LEN(Forms!$A17)>0,Forms!$A17,"") | GT17: =IF(LEN(DataDictionaries!$A17)>0,DataDictionaries!$A17,"")
A18: DM | B18: CBRSNOTH | C18: 7 | E18: CBRSNOTH | F18: TRUE | G18: CBRSNOTH | H18: $200 | L18: LongText | N18: 0 | O18: If Other, specify | S18: FALSE | T18: FALSE | V18: Specify other | Y18: TRUE | Z18: FALSE | AA18: FALSE | AB18: FALSE | AD18: FALSE | AE18: FALSE | AF18: FALSE | AG18: FALSE | AH18: FALSE | AI18: FALSE | AJ18: FALSE | AK18: FALSE | AS18: FALSE | AT18: 84054 | AU18: 78599 | AV18: 77172 | AW18: 72292 | AZ18: Bilirubin Direct (BILIND) | GR18: =IF(LEN(UnitDictionaries!$A18)>0,UnitDictionaries!$A18,"") | GS18: =IF(LEN(Forms!$A18)>0,Forms!$A18,"") | GT18: =IF(LEN(DataDictionaries!$A18)>0,DataDictionaries!$A18,"")
A19: DM | B19: ETHNIC | C19: 8 | E19: ETHNIC | F19: TRUE | G19: ETHNIC | H19: $22 | I19: ETHNICITY | L19: RadioButton (Vertical) | N19: 0 | O19: Ethnicity | S19: FALSE | T19: FALSE | V19: Ethnicity | Y19: TRUE | Z19: FALSE | AA19: TRUE | AB19: FALSE | AD19: FALSE | AE19: FALSE | AF19: FALSE | AG19: FALSE | AH19: FALSE | AI19: FALSE | AJ19: FALSE | AK19: FALSE | AR19: Data Management | AS19: FALSE | AT19: 84055 | AU19: 78600 | AV19: 77173 | AW19: 72293 | AZ19: Bilirubin Total (BILIT) | GR19: =IF(LEN(UnitDictionaries!$A19)>0,UnitDictionaries!$A19,"") | GS19: =IF(LEN(Forms!$A19)>0,Forms!$A19,"") | GT19: =IF(LEN(DataDictionaries!$A19)>0,DataDictionaries!$A19,"")
A20: DM | B20: RACE | C20: 9 | E20: RACE | F20: TRUE | G20: RACE | H20: $6 | I20: RACE | L20: DropDownList | N20: 0 | O20: Race | S20: FALSE | T20: FALSE | V20: Race | Y20: TRUE | Z20: FALSE | AA20: TRUE | AB20: FALSE | AD20: FALSE | AE20: FALSE | AF20: FALSE | AG20: FALSE | AH20: FALSE | AI20: FALSE | AJ20: FALSE | AK20: FALSE | AS20: FALSE | AT20: 84056 | AU20: 78601 | AV20: 77174 | AW20: 72294 | AZ20: Blood Urea Nitrogen (BUN) | GR20: =IF(LEN(UnitDictionaries!$A20)>0,UnitDictionaries!$A20,"") | GS20: =IF(LEN(Forms!$A20)>0,Forms!$A20,"") | GT20: =IF(LEN(DataDictionaries!$A20)>0,DataDictionaries!$A20,"")
A21: DM | B21: RACEOTH | C21: 10 | E21: RACEOTH | F21: TRUE | G21: RACEOTH | H21: $200 | L21: LongText | N21: 0 | O21: If Other, specify | S21: FALSE | T21: FALSE | V21: Specify other | Y21: TRUE | Z21: FALSE | AA21: FALSE | AB21: FALSE | AD21: FALSE | AE21: FALSE | AF21: FALSE | AG21: FALSE | AH21: FALSE | AI21: FALSE | AJ21: FALSE | AK21: FALSE | AS21: FALSE | AT21: 84057 | AU21: 78602 | AV21: 77175 | AW21: 72295 | AZ21: Calcium (CA) | GR21: =IF(LEN(UnitDictionaries!$A21)>0,UnitDictionaries!$A21,"") | GS21: =IF(LEN(Forms!$A21)>0,Forms!$A21,"") | GT21: =IF(LEN(DataDictionaries!$A21)>0,DataDictionaries!$A21,"")
A22: CONTD | B22: DSCONTYN | C22: 1 | E22: DSCONTYN | F22: TRUE | G22: DSCONTYN | H22: $1 | I22: YesNo | L22: RadioButton (Vertical) | N22: 0 | O22: Will subject continue to the next visit? | S22: FALSE | T22: FALSE | Y22: TRUE | Z22: FALSE | AA22: TRUE | AB22: FALSE | AD22: FALSE | AE22: FALSE | AF22: FALSE | AG22: FALSE | AH22: FALSE | AI22: FALSE | AJ22: FALSE | AK22: FALSE | AR22: Data Management | AS22: FALSE | AT22: 84045 | AU22: 78716 | AV22: 77163 | AW22: 72546 | AZ22: Potassium (K) | GR22: =IF(LEN(UnitDictionaries!$A22)>0,UnitDictionaries!$A22,"") | GS22: =IF(LEN(Forms!$A22)>0,Forms!$A22,"") | GT22: =IF(LEN(DataDictionaries!$A22)>0,DataDictionaries!$A22,"")
A23: IE | B23: IEYN | C23: 1 | E23: IEYN | F23: TRUE | G23: IEYN | H23: $1 | I23: YesNo | L23: RadioButton (Vertical) | N23: 0 | O23: Is Subject eligible for this Study? | S23: FALSE | T23: FALSE | V23: Is Subject eligible for this Study | Y23: TRUE | Z23: FALSE | AA23: TRUE | AB23: FALSE | AD23: FALSE | AE23: FALSE | AF23: FALSE | AG23: FALSE | AH23: FALSE | AI23: FALSE | AJ23: FALSE | AK23: FALSE | AS23: FALSE | AT23: 84065 | AU23: 78740 | AV23: 77182 | AW23: 72284 | AZ23: Ketones | GR23: =IF(LEN(UnitDictionaries!$A23)>0,UnitDictionaries!$A23,"") | GS23: =IF(LEN(Forms!$A23)>0,Forms!$A23,"") | GT23: =IF(LEN(DataDictionaries!$A23)>0,DataDictionaries!$A23,"")
A24: IE | B24: IE_HEADER | C24: 2 | E24: IE_HEADER | F24: TRUE | L24: Text | N24: 0 | O24: Enter all criteria which were not met below | S24: FALSE | T24: FALSE | Y24: FALSE | Z24: FALSE | AA24: TRUE | AB24: FALSE | AD24: FALSE | AE24: FALSE | AF24: FALSE | AG24: FALSE | AH24: FALSE | AI24: FALSE | AJ24: FALSE | AK24: TRUE | AS24: FALSE | AT24: 84063 | AU24: 78738 | AZ24: Lactate Dehydrogenase (LDH) | GR24: =IF(LEN(UnitDictionaries!$A24)>0,UnitDictionaries!$A24,"") | GS24: =IF(LEN(Forms!$A24)>0,Forms!$A24,"") | GT24: =IF(LEN(DataDictionaries!$A24)>0,DataDictionaries!$A24,"")
A25: IE | B25: IETESTCD | C25: 3 | E25: IETESTCD | F25: TRUE | G25: IETESTCD | H25: 2 | I25: Criterion Number | L25: DropDownList | N25: 0 | O25: Criterion Identifier | S25: FALSE | T25: TRUE | V25: Criterion Identifier | Y25: FALSE | Z25: FALSE | AA25: TRUE | AB25: FALSE | AD25: FALSE | AE25: FALSE | AF25: FALSE | AG25: FALSE | AH25: FALSE | AI25: FALSE | AJ25: FALSE | AK25: FALSE | AR25: Data Management | AS25: FALSE | AT25: 84064 | AU25: 78739 | AV25: 77181 | AW25: 72285 | AZ25: Lymphocytes (Absolute) | GR25: =IF(LEN(UnitDictionaries!$A25)>0,UnitDictionaries!$A25,"") | GS25: =IF(LEN(Forms!$A25)>0,Forms!$A25,"") | GT25: =IF(LEN(DataDictionaries!$A25)>0,DataDictionaries!$A25,"")
AZ26: Magnesium | GR26: =IF(LEN(UnitDictionaries!$A26)>0,UnitDictionaries!$A26,"") | GS26: =IF(LEN(Forms!$A26)>0,Forms!$A26,"") | GT26: =IF(LEN(DataDictionaries!$A26)>0,DataDictionaries!$A26,"")
AZ27: Monocytes (Absolutes) | GR27: =IF(LEN(UnitDictionaries!$A27)>0,UnitDictionaries!$A27,"") | GS27: =IF(LEN(Forms!$A27)>0,Forms!$A27,"") | GT27: =IF(LEN(DataDictionaries!$A27)>0,DataDictionaries!$A27,"")
AZ28: Neutrophils (Absolute) | GR28: =IF(LEN(UnitDictionaries!$A28)>0,UnitDictionaries!$A28,"") | GS28: =IF(LEN(Forms!$A28)>0,Forms!$A28,"") | GT28: =IF(LEN(DataDictionaries!$A28)>0,DataDictionaries!$A28,"")
AZ29: Phosphate(PHOS) | GR29: =IF(LEN(UnitDictionaries!$A29)>0,UnitDictionaries!$A29,"") | GS29: =IF(LEN(Forms!$A29)>0,Forms!$A29,"") | GT29: =IF(LEN(DataDictionaries!$A29)>0,DataDictionaries!$A29,"")
AZ30: Platelets | GR30: =IF(LEN(UnitDictionaries!$A30)>0,UnitDictionaries!$A30,"") | GS30: =IF(LEN(Forms!$A30)>0,Forms!$A30,"") | GT30: =IF(LEN(DataDictionaries!$A30)>0,DataDictionaries!$A30,"")
AZ31: Prolactin | GR31: =IF(LEN(UnitDictionaries!$A31)>0,UnitDictionaries!$A31,"") | GS31: =IF(LEN(Forms!$A31)>0,Forms!$A31,"") | GT31: =IF(LEN(DataDictionaries!$A31)>0,DataDictionaries!$A31,"")
AZ32: Prothrombin time | GR32: =IF(LEN(UnitDictionaries!$A32)>0,UnitDictionaries!$A32,"") | GS32: =IF(LEN(Forms!$A32)>0,Forms!$A32,"") | GT32: =IF(LEN(DataDictionaries!$A32)>0,DataDictionaries!$A32,"")
AZ33: RBC(Erythrocytes) | GR33: =IF(LEN(UnitDictionaries!$A33)>0,UnitDictionaries!$A33,"") | GS33: =IF(LEN(Forms!$A33)>0,Forms!$A33,"") | GT33: =IF(LEN(DataDictionaries!$A33)>0,DataDictionaries!$A33,"")
AZ34: Reticulocyte | GR34: =IF(LEN(UnitDictionaries!$A34)>0,UnitDictionaries!$A34,"") | GS34: =IF(LEN(Forms!$A34)>0,Forms!$A34,"") | GT34: =IF(LEN(DataDictionaries!$A34)>0,DataDictionaries!$A34,"")
AZ35: Sodium | GR35: =IF(LEN(UnitDictionaries!$A35)>0,UnitDictionaries!$A35,"") | GS35: =IF(LEN(Forms!$A35)>0,Forms!$A35,"") | GT35: =IF(LEN(DataDictionaries!$A35)>0,DataDictionaries!$A35,"")
AZ36: Specific Gravity | GR36: =IF(LEN(UnitDictionaries!$A36)>0,UnitDictionaries!$A36,"") | GS36: =IF(LEN(Forms!$A36)>0,Forms!$A36,"") | GT36: =IF(LEN(DataDictionaries!$A36)>0,DataDictionaries!$A36,"")
AZ37: Thrombin time | GR37: =IF(LEN(UnitDictionaries!$A37)>0,UnitDictionaries!$A37,"") | GS37: =IF(LEN(Forms!$A37)>0,Forms!$A37,"") | GT37: =IF(LEN(DataDictionaries!$A37)>0,DataDictionaries!$A37,"")
... AZ98: Tumour Size | GR98: =IF(LEN(UnitDictionaries!$A98)>0,UnitDictionaries!$A98,"") | GS98: =IF(LEN(Forms!$A98)>0,Forms!$A98,"") | GT98: =IF(LEN(DataDictionaries!$A98)>0,DataDictionaries!$A98,"")
GR99: =IF(LEN(UnitDictionaries!$A99)>0,UnitDictionaries!$A99,"") | GS99: =IF(LEN(Forms!$A99)>0,Forms!$A99,"") | GT99: =IF(LEN(DataDictionaries!$A99)>0,DataDictionaries!$A99,"")
GR100: =IF(LEN(UnitDictionaries!$A100)>0,UnitDictionaries!$A100,"") | GS100: =IF(LEN(Forms!$A100)>0,Forms!$A100,"") | GT100: =IF(LEN(DataDictionaries!$A100)>0,DataDictionaries!$A100,"")
...

Sheet Folders
A1: OID | B1: Ordinal | C1: FolderName | D1: AccessDays | E1: StartWinDays | F1: Targetdays | G1: EndWinDays | H1: OverDueDays | I1: CloseDays | J1: ParentFolderOID | K1: IsReusable | L1: DownloadedFromObjectId | M1: SourceObjectId | N1: SourceUrlId
A2: SCRN | B2: 1 | C2: Screening | K2: FALSE | L2: 4264 | M2: 3955
A3: BASE | B3: 2 | C3: Day 1 (Baseline) | E3: 0 | F3: 0 | G3: 0 | K3: FALSE | L3: 4265 | M3: 3956

Sheet DataDictionaries
A1: DataDictionaryName | B1: OID | C1: DownloadedFromObjectId | D1: SourceObjectId | E1: SourceUrlId
A2: YesNo | B2: YESNO | C2: 14078 | D2: 13218
A3: ICPROT | B3: ICPROT | C3: 14079 | D3: 13206
A4: CBP | B4: CBP | C4: 14080 | D4: 13192
A5: ETHNICITY | B5: ETHNICITY | C5: 14081 | D5: 13203
A6: RACE | B6: RACE | C6: 14082 | D6: 13213
A7: SEX | B7: SEX | C7: 14083 | D7: 13216
A8: Criterion Number | B8: CRITERIONNUMBER | C8: 14084 | D8: 13198

Sheet DataDictionaryEntries
A1: DataDictionaryName | B1: CodedData | C1: Ordinal | D1: UserDataString | E1: Specify
A2: YesNo | B2: Y | C2: 1 | D2: Yes | E2: FALSE | GR2: =IF(LEN(DataDictionaries!$A2)>0,DataDictionaries!$A2,"") -> YesNo
A3: YesNo | B3: N | C3: 2 | D3: No | E3: FALSE | GR3: =IF(LEN(DataDictionaries!$A3)>0,DataDictionaries!$A3,"") -> ICPROT
A4: ICPROT | B4: 1 | C4: 1 | D4: 1.0 | E4: FALSE | GR4: =IF(LEN(DataDictionaries!$A4)>0,DataDictionaries!$A4,"") -> CBP
A5: ICPROT | B5: 2 | C5: 2 | D5: 2.0 | E5: FALSE | GR5: =IF(LEN(DataDictionaries!$A5)>0,DataDictionaries!$A5,"") -> ETHNICITY
A6: ICPROT | B6: 3 | C6: 3 | D6: 3.0 | E6: FALSE | GR6: =IF(LEN(DataDictionaries!$A6)>0,DataDictionaries!$A6,"") -> RACE
A7: ICPROT | B7: 4 | C7: 4 | D7: 4.0 | E7: FALSE | GR7: =IF(LEN(DataDictionaries!$A7)>0,DataDictionaries!$A7,"") -> SEX
A8: ICPROT | B8: 5 | C8: 5 | D8: 5.0 | E8: FALSE | GR8: =IF(LEN(DataDictionaries!$A8)>0,DataDictionaries!$A8,"") -> Criterion Number
A9: ICPROT | B9: 6 | C9: 6 | D9: 6.0 | E9: FALSE | GR9: =IF(LEN(DataDictionaries!$A9)>0,DataDictionaries!$A9,"")
A10: ICPROT | B10: 7 | C10: 7 | D10: 7.0 | E10: FALSE | GR10: =IF(LEN(DataDictionaries!$A10)>0,DataDictionaries!$A10,"")
A11: ICPROT | B11: 8 | C11: 8 | D11: 8.0 | E11: FALSE | GR11: =IF(LEN(DataDictionaries!$A11)>0,DataDictionaries!$A11,"")
A12: ICPROT | B12: 9 | C12: 9 | D12: 9.0 | E12: FALSE | GR12: =IF(LEN(DataDictionaries!$A12)>0,DataDictionaries!$A12,"")
A13: ICPROT | B13: 10 | C13: 10 | D13: 10.0 | E13: FALSE | GR13: =IF(LEN(DataDictionaries!$A13)>0,DataDictionaries!$A13,"")
... A54: Criterion Number | B54: 26 | C54: 26 | D54: Exclusion 17 | E54: FALSE | GR54: =IF(LEN(DataDictionaries!$A54)>0,DataDictionaries!$A54,"")
GR55: =IF(LEN(DataDictionaries!$A55)>0,DataDictionaries!$A55,"")
GR56: =IF(LEN(DataDictionaries!$A56)>0,DataDictionaries!$A56,"")
GR57: =IF(LEN(DataDictionaries!$A57)>0,DataDictionaries!$A57,"")
GR58: =IF(LEN(DataDictionaries!$A58)>0,DataDictionaries!$A58,"")
GR59: =IF(LEN(DataDictionaries!$A59)>0,DataDictionaries!$A59,"")
GR60: =IF(LEN(DataDictionaries!$A60)>0,DataDictionaries!$A60,"")
GR61: =IF(LEN(DataDictionaries!$A61)>0,DataDictionaries!$A61,"")
GR62: =IF(LEN(DataDictionaries!$A62)>0,DataDictionaries!$A62,"")
GR63: =IF(LEN(DataDictionaries!$A63)>0,DataDictionaries!$A63,"")
GR64: =IF(LEN(DataDictionaries!$A64)>0,DataDictionaries!$A64,"")
GR65: =IF(LEN(DataDictionaries!$A65)>0,DataDictionaries!$A65,"")
GR66: =IF(LEN(DataDictionaries!$A66)>0,DataDictionaries!$A66,"")
... GR74: =IF(LEN(DataDictionaries!$A74)>0,DataDictionaries!$A74,"")

Sheet UnitDictionaries
A1: UnitDictionaryName | B1: StandardUnitName | C1: OID | D1: DownloadedFromObjectId | E1: SourceObjectId | F1: SourceUrlId
GR2: =IF(LEN(UnitDictionaryEntries!$H2)>0,UnitDictionaryEntries!$H2,"")
GR3: =IF(LEN(UnitDictionaryEntries!$H3)>0,UnitDictionaryEntries!$H3,"")
GR4: =IF(LEN(UnitDictionaryEntries!$H4)>0,UnitDictionaryEntries!$H4,"")
GR5: =IF(LEN(UnitDictionaryEntries!$H5)>0,UnitDictionaryEntries!$H5,"")
GR6: =IF(LEN(UnitDictionaryEntries!$H6)>0,UnitDictionaryEntries!$H6,"")
GR7: =IF(LEN(UnitDictionaryEntries!$H7)>0,UnitDictionaryEntries!$H7,"")
GR8: =IF(LEN(UnitDictionaryEntries!$H8)>0,UnitDictionaryEntries!$H8,"")
GR9: =IF(LEN(UnitDictionaryEntries!$H9)>0,UnitDictionaryEntries!$H9,"")
GR10: =IF(LEN(UnitDictionaryEntries!$H10)>0,UnitDictionaryEntries!$H10,"")
GR11: =IF(LEN(UnitDictionaryEntries!$H11)>0,UnitDictionaryEntries!$H11,"")
GR12: =IF(LEN(UnitDictionaryEntries!$H12)>0,UnitDictionaryEntries!$H12,"")
GR13: =IF(LEN(UnitDictionaryEntries!$H13)>0,UnitDictionaryEntries!$H13,"")
... GR22: =IF(LEN(UnitDictionaryEntries!$H22)>0,UnitDictionaryEntries!$H22,"")

Sheet UnitDictionaryEntries
A1: UnitDictionaryName | B1: CodedUnit | C1: Ordinal | D1: ConstantA | E1: ConstantB | F1: ConstantC | G1: ConstantK | H1: UnitString
GR2: =IF(LEN(UnitDictionaries!$A2)>0,UnitDictionaries!$A2,"")
GR3: =IF(LEN(UnitDictionaries!$A3)>0,UnitDictionaries!$A3,"")
GR4: =IF(LEN(UnitDictionaries!$A4)>0,UnitDictionaries!$A4,"")
GR5: =IF(LEN(UnitDictionaries!$A5)>0,UnitDictionaries!$A5,"")
GR6: =IF(LEN(UnitDictionaries!$A6)>0,UnitDictionaries!$A6,"")
GR7: =IF(LEN(UnitDictionaries!$A7)>0,UnitDictionaries!$A7,"")
GR8: =IF(LEN(UnitDictionaries!$A8)>0,UnitDictionaries!$A8,"")
GR9: =IF(LEN(UnitDictionaries!$A9)>0,UnitDictionaries!$A9,"")
GR10: =IF(LEN(UnitDictionaries!$A10)>0,UnitDictionaries!$A10,"")
GR11: =IF(LEN(UnitDictionaries!$A11)>0,UnitDictionaries!$A11,"")
GR12: =IF(LEN(UnitDictionaries!$A12)>0,UnitDictionaries!$A12,"")
GR13: =IF(LEN(UnitDictionaries!$A13)>0,UnitDictionaries!$A13,"")
... GR42: =IF(LEN(UnitDictionaries!$A42)>0,UnitDictionaries!$A42,"")

Sheet Matrices
A1: MatrixName | B1: OID | C1: Addable | D1: Maximum | E1: DownloadedFromObjectId | F1: SourceObjectId | G1: SourceUrlId
A2: Screening | B2: SCRN | C2: FALSE | D2: 0 | E2: 4359 | F2: 4059
A3: Primary | B3: PRIMARY | C3: FALSE | D3: 0 | E3: 4360 | F3: 4060
A4: Baseline SV | B4: BASE_SV | C4: FALSE | D4: 0 | E4: 4361 | F4: 4062

Sheet Matrix1#SCRN
A1: Matrix: SCRN | B1: Subject | C1: SCRN | D1: BASE
A2: SUBJECT
A3: SV
A4: IC
A5: DM
A6: CONTD
A7: IE

Sheet Matrix2#PRIMARY
A1: Matrix: PRIMARY | B1: Subject | C1: SCRN | D1: BASE
A2: SUBJECT
A3: SV | C3: X
A4: IC | C4: X
A5: DM | C5: X
A6: CONTD
A7: IE | C7: X

Sheet Matrix3#BASESV
A1: Matrix: BASE_SV | B1: Subject | C1: SCRN | D1: BASE
A2: SUBJECT
A3: SV | D3: X
A4: IC
A5: DM
A6: CONTD | D6: X
A7: IE

Sheet Checks
A1: CheckName | B1: CheckActive | C1: BypassDuringMigration | D1: Infix | E1: CopySource | F1: NeedsRetesting | G1: RetestingReason | H1: OID | I1: DownloadedFromObjectId | J1: SourceObjectId | K1: SourceUrlId
A2: DYN_SV_SVOCCUR_N | B2: TRUE | C2: FALSE | D2: If SVOCCUR in Visit Date with record position 0 IsEqualTo N then... SVOCCUR in Visit Date with record position 0 IsPresent, and Set the datapoint used by SVREASND in Visit Date with record position 0 to Visible (Enter Empty When Not Visible) | E2: Project Version ALXN1720-NEPH-102/ALXN1720-NEPH-102_Final_v1.0 | F2: TRUE | G2: Target has been changed since the time of copy. | H2: DYN_SV_SVOCCUR_N | I2: 184426 | J2: 172078
A3: DYN_SV_SVOCCUR_Y | B3: TRUE | C3: FALSE | D3: If SVOCCUR in Visit Date with record position 0 IsEqualTo Y then... SVOCCUR in Visit Date with record position 0 IsPresent, and Set the datapoint used by SVDAT in Visit Date with record position 0 to Visible (Enter Empty When Not Visible) | E3: Project Version ALXN1720-NEPH-102/ALXN1720-NEPH-102_Final_v1.0 | F3: TRUE | G3: Target has been changed since the time of copy. | H3: DYN_SV_SVOCCUR_Y | I3: 184427 | J3: 172079
A4: DYN_IC_ICYN | B4: TRUE | C4: FALSE | D4: If ICYN in Informed Consent with record position 0 IsEqualTo Y then... ICYN in Informed Consent with record position 0 IsPresent, and Set the datapoint used by RFICDAT in Informed Consent with record position 0 to Visible (Enter Empty When Not Visible), and Set the datapoint used by ICTIM in Informed Consent with record position 0 to Visible (Enter Empty When Not Visible), and Set the datapoint used by ICPROT in Informed Consent with record position 0 to Visible (Enter Empty When Not Visible) | E4: Project Version ALXN1720-NEPH-102/ALXN1720-NEPH-102_Final_v1.0 | F4: TRUE | G4: Target has been changed since the time of copy. | H4: DYN_IC_ICYN | I4: 184429 | J4: 172081
A5: DYN_DM_CBRSN | B5: TRUE | C5: FALSE | D5: If (CBPYN in Demographics with record position 0 IsEqualTo N) And (CBRSN in Demographics with record position 0 IsEqualTo 5) then... Set the datapoint used by CBRSNOTH in Demographics with record position 0 to Visible (Enter Empty When Not Visible), and CBPYN in Demographics with record position 0 IsPresent | E5: Project Version ALXN1720-NEPH-102/ALXN1720-NEPH-102_Final_v1.0 | F5: TRUE | G5: Target has been changed since the time of copy. | H5: DM01 | I5: 184431 | J5: 172131
A6: DYN_DM_CBPYN | B6: TRUE | C6: FALSE | D6: If CBPYN in Demographics with record position 0 IsEqualTo N then... Set the datapoint used by CBRSN in Demographics with record position 0 to Visible (Enter Empty When Not Visible), and CBPYN in Demographics with record position 0 IsPresent | E6: Project Version ALXN1720-NEPH-102/ALXN1720-NEPH-102_Final_v1.0 | F6: TRUE | G6: Target has been changed since the time of copy. | H6: DM02 | I6: 184432 | J6: 172132
A7: DYN_DM_SEX | B7: TRUE | C7: FALSE | D7: If SEX in Demographics with record position 0 IsEqualTo F then... SEX in Demographics with record position 0 IsPresent, and Set the datapoint used by CBPYN in Demographics with record position 0 to Visible (Enter Empty When Not Visible) | E7: Project Version ALXN1720-NEPH-102/ALXN1720-NEPH-102_Final_v1.0 | F7: TRUE | G7: Target has been changed since the time of copy. | H7: DM03 | I7: 184433 | J7: 172133
A8: DYN_DM_RACE | B8: TRUE | C8: FALSE | D8: If RACE in Demographics with record position 0 IsEqualTo OTHER then... RACE in Demographics with record position 0 IsPresent, and Set the datapoint used by RACEOTH in Demographics with record position 0 to Visible (Enter Empty When Not Visible) | E8: Project Version ALXN1720-NEPH-102/ALXN1720-NEPH-102_Final_v1.0 | F8: TRUE | G8: Target has been changed since the time of copy. | H8: DM04 | I8: 184434 | J8: 172134
A9: DYN_DM_CBRSN1DAT | B9: TRUE | C9: FALSE | D9: If (CBRSN in Demographics with record position 0 IsEqualTo 3) Or (CBRSN in Demographics with record position 0 IsEqualTo 4) then... CBRSN in Demographics with record position 0 IsPresent, and Set the datapoint used by CBRSN1DAT in Demographics with record position 0 to Visible (Enter Empty When Not Visible) | E9: Project Version ALXN1720-NEPH-102/ALXN1720-NEPH-102_Final_v1.0 | F9: TRUE | G9: Target has been changed since the time of copy. | H9: DM05 | I9: 184435 | J9: 172135
A10: EC_SV_010 | B10: TRUE | C10: FALSE | D10: If ((SVDAT in Visit Date with record position 0 IsNotEmpty) And (RFICDAT in Informed Consent in Screening with record position 0 IsNotEmpty)) And (SVDAT in Visit Date with record position 0 IsLessThan RFICDAT in Informed Consent in Screening with record position 0) then... open a query to Site from System on SVDAT in Visit Date with record position 0, displaying "Visit Date is prior to the Date of Informed Consent. Please review and update, else clarify."( requires response )( requires manual close ) | E10: Project Version ALXN1720-NEPH-102/ALXN1720-NEPH-102_Final_v1.0 | F10: TRUE | G10: Possible issues in matrix environments of the following forms: SV. Target has been changed since the time of copy. | H10: SV1 | I10: 184440 | J10: 172368
A11: D_CF_SUBJID_01 | B11: TRUE | C11: FALSE | D11: If SUBMDTM in Subject ID with record position 0 IsPresent then... execute the "CF_SUBJECT_01" custom function | E11: Project Version ALXN1720-NEPH-102/ALXN1720-NEPH-102_Final_v1.0 | F11: TRUE | G11: References the following custom functions: CF_SUBJECT_01. | H11: D_CF_SUBJID_01 | I11: 184484 | J11: 172046
A12: MERGE_SCRN | B12: TRUE | C12: FALSE | D12: If (IEYN in Eligibility in Screening with record position 0 IsEqualTo Y) And (SVDAT in Visit Date in Screening with record position 0 IsNotEmpty) then... merge the "Screening" matrix on IEYN in Eligibility in Screening with record position 0 | E12: Project Version ALXN1720-NEPH-102/ALXN1720-NEPH-102_Final_v1.0 | F12: TRUE | G12: Contains AddMatrix or MergeMatrix actions. | H12: MERGE_SCRN | I12: 184485 | J12: 172056
A13: MERGE_BASE_SV | B13: TRUE | C13: FALSE | D13: If IEYN in Eligibility in Screening with record position 0 IsEqualTo Y then... merge the "Baseline SV" matrix on IEYN in Eligibility in Screening with record position 0 | E13: Project Version ALXN1720-NEPH-102/ALXN1720-NEPH-102_Final_v1.0 | F13: TRUE | G13: Contains AddMatrix or MergeMatrix actions. | H13: MERGE_BASE_SV | I13: 184486 | J13: 172058
... A16: EC_DM_010 | B16: TRUE | C16: FALSE | D16: If ((AGE in Demographics with record position 0 IsLessThan 19) Or (AGE in Demographics with record position 0 IsGreaterThan 65)) And (IEYN in Eligibility in Screening with record position 0 IsEqualTo Y) then... open a query to Site from System on AGE in Demographics with record position 0, displaying "Age of participant is less than 19 years or greater than 65 years. Please review and confirm subject's eligibility, else, reconcile."( requires response )( requires manual close ) | E16: Project Version ALXN1720-NEPH-102/ALXN1720-NEPH-102_Final_v1.0 | F16: TRUE | G16: Target has been changed since the time of copy. | H16: DM3 | I16: 184489 | J16: 172294

Sheet CheckSteps
A1: CheckName | B1: StepOrdinal | C1: CheckFunction | D1: StaticValue | E1: DataFormat | F1: VariableOID | G1: FolderOID | H1: FormOID | I1: FieldOID | J1: RecordPosition | K1: CustomFunction | L1: LogicalRecordPosition | M1: Scope | N1: OrderBy | O1: FormRepeatNumber | P1: FolderRepeatNumber | Q1: CheckFunction_ValCol
A2: DYN_SV_SVOCCUR_N | B2: 1 | E2: CodedValue | F2: SVOCCUR | H2: SV | I2: SVOCCUR | J2: 0 | Q2: CustomFunction | GR2: =IF(LEN(Checks!$A2)>0,Checks!$A2,"") -> DYN_SV_SVOCCUR_N | GS2: =IF(LEN(Folders!$A2)>0,Folders!$A2,"") -> SCRN | GT2: =IF(LEN(CustomFunctions!$A2)>0,CustomFunctions!$A2,"") -> CF_SUBJECT_01 | GU2: =IF(LEN(Fields!$G2)>0,Fields!$G2,"") | GV2: =IF(LEN(Fields!$B2)>0,Fields!$B2,"") -> SUB_HEADER
A3: DYN_SV_SVOCCUR_N | B3: 2 | D3: N | E3: $1 | Q3: IsEmpty | GR3: =IF(LEN(Checks!$A3)>0,Checks!$A3,"") -> DYN_SV_SVOCCUR_Y | GS3: =IF(LEN(Folders!$A3)>0,Folders!$A3,"") -> BASE | GT3: =IF(LEN(CustomFunctions!$A3)>0,CustomFunctions!$A3,"") -> CF_SUBJECT_02 | GU3: =IF(LEN(Fields!$G3)>0,Fields!$G3,"") -> SUBJID | GV3: =IF(LEN(Fields!$B3)>0,Fields!$B3,"") -> SUBJID
A4: DYN_SV_SVOCCUR_N | B4: 3 | C4: IsEqualTo | Q4: IsNotEmpty | GR4: =IF(LEN(Checks!$A4)>0,Checks!$A4,"") -> DYN_IC_ICYN | GS4: =IF(LEN(Folders!$A4)>0,Folders!$A4,"") | GT4: =IF(LEN(CustomFunctions!$A4)>0,CustomFunctions!$A4,"") | GU4: =IF(LEN(Fields!$G4)>0,Fields!$G4,"") -> SUBMDTM | GV4: =IF(LEN(Fields!$B4)>0,Fields!$B4,"") -> SUBMDTM
A5: DYN_SV_SVOCCUR_Y | B5: 1 | E5: CodedValue | F5: SVOCCUR | H5: SV | I5: SVOCCUR | J5: 0 | Q5: Contains | GR5: =IF(LEN(Checks!$A5)>0,Checks!$A5,"") -> DYN_DM_CBRSN | GS5: =IF(LEN(Folders!$A5)>0,Folders!$A5,"") | GT5: =IF(LEN(CustomFunctions!$A5)>0,CustomFunctions!$A5,"") | GU5: =IF(LEN(Fields!$G5)>0,Fields!$G5,"") -> SVOCCUR | GV5: =IF(LEN(Fields!$B5)>0,Fields!$B5,"") -> SVOCCUR
A6: DYN_SV_SVOCCUR_Y | B6: 2 | D6: Y | E6: $1 | Q6: StartsWith | GR6: =IF(LEN(Checks!$A6)>0,Checks!$A6,"") -> DYN_DM_CBPYN | GS6: =IF(LEN(Folders!$A6)>0,Folders!$A6,"") | GT6: =IF(LEN(CustomFunctions!$A6)>0,CustomFunctions!$A6,"") | GU6: =IF(LEN(Fields!$G6)>0,Fields!$G6,"") -> SVREASND | GV6: =IF(LEN(Fields!$B6)>0,Fields!$B6,"") -> SVREASND
A7: DYN_SV_SVOCCUR_Y | B7: 3 | C7: IsEqualTo | Q7: IsLessThan | GR7: =IF(LEN(Checks!$A7)>0,Checks!$A7,"") -> DYN_DM_SEX | GS7: =IF(LEN(Folders!$A7)>0,Folders!$A7,"") | GT7: =IF(LEN(CustomFunctions!$A7)>0,CustomFunctions!$A7,"") | GU7: =IF(LEN(Fields!$G7)>0,Fields!$G7,"") -> SVDAT | GV7: =IF(LEN(Fields!$B7)>0,Fields!$B7,"") -> SVDAT
A8: DYN_IC_ICYN | B8: 1 | E8: CodedValue | F8: ICYN | H8: IC | I8: ICYN | J8: 0 | Q8: IsLessThanOrEqualTo | GR8: =IF(LEN(Checks!$A8)>0,Checks!$A8,"") -> DYN_DM_RACE | GS8: =IF(LEN(Folders!$A8)>0,Folders!$A8,"") | GT8: =IF(LEN(CustomFunctions!$A8)>0,CustomFunctions!$A8,"") | GU8: =IF(LEN(Fields!$G8)>0,Fields!$G8,"") -> ICYN | GV8: =IF(LEN(Fields!$B8)>0,Fields!$B8,"") -> ICYN
A9: DYN_IC_ICYN | B9: 2 | D9: Y | E9: $1 | Q9: IsGreaterThan | GR9: =IF(LEN(Checks!$A9)>0,Checks!$A9,"") -> DYN_DM_CBRSN1DAT | GS9: =IF(LEN(Folders!$A9)>0,Folders!$A9,"") | GT9: =IF(LEN(CustomFunctions!$A9)>0,CustomFunctions!$A9,"") | GU9: =IF(LEN(Fields!$G9)>0,Fields!$G9,"") -> RFICDAT | GV9: =IF(LEN(Fields!$B9)>0,Fields!$B9,"") -> RFICDAT
A10: DYN_IC_ICYN | B10: 3 | C10: IsEqualTo | Q10: IsGreaterThanOrEqualTo | GR10: =IF(LEN(Checks!$A10)>0,Checks!$A10,"") -> EC_SV_010 | GS10: =IF(LEN(Folders!$A10)>0,Folders!$A10,"") | GT10: =IF(LEN(CustomFunctions!$A10)>0,CustomFunctions!$A10,"") | GU10: =IF(LEN(Fields!$G10)>0,Fields!$G10,"") -> ICTIM | GV10: =IF(LEN(Fields!$B10)>0,Fields!$B10,"") -> ICTIM
A11: DYN_DM_CBRSN | B11: 1 | E11: CodedValue | F11: CBPYN | H11: DM | I11: CBPYN | J11: 0 | Q11: IsEqualTo | GR11: =IF(LEN(Checks!$A11)>0,Checks!$A11,"") -> D_CF_SUBJID_01 | GS11: =IF(LEN(Folders!$A11)>0,Folders!$A11,"") | GT11: =IF(LEN(CustomFunctions!$A11)>0,CustomFunctions!$A11,"") | GU11: =IF(LEN(Fields!$G11)>0,Fields!$G11,"") -> ICPROT | GV11: =IF(LEN(Fields!$B11)>0,Fields!$B11,"") -> ICPROT
A12: DYN_DM_CBRSN | B12: 2 | D12: N | E12: $1 | Q12: IsNonConformant | GR12: =IF(LEN(Checks!$A12)>0,Checks!$A12,"") -> MERGE_SCRN | GS12: =IF(LEN(Folders!$A12)>0,Folders!$A12,"") | GT12: =IF(LEN(CustomFunctions!$A12)>0,CustomFunctions!$A12,"") | GU12: =IF(LEN(Fields!$G12)>0,Fields!$G12,"") -> BRTHDAT | GV12: =IF(LEN(Fields!$B12)>0,Fields!$B12,"") -> BRTHDAT
A13: DYN_DM_CBRSN | B13: 3 | C13: IsEqualTo | Q13: IsNotEqualTo | GR13: =IF(LEN(Checks!$A13)>0,Checks!$A13,"") -> MERGE_BASE_SV | GS13: =IF(LEN(Folders!$A13)>0,Folders!$A13,"") | GT13: =IF(LEN(CustomFunctions!$A13)>0,CustomFunctions!$A13,"") | GU13: =IF(LEN(Fields!$G13)>0,Fields!$G13,"") -> AGE | GV13: =IF(LEN(Fields!$B13)>0,Fields!$B13,"") -> AGE
A14: DYN_DM_CBRSN | B14: 4 | E14: CodedValue | F14: CBRSN | H14: DM | I14: CBRSN | J14: 0 | Q14: InLocalLabRange | GR14: =IF(LEN(Checks!$A14)>0,Checks!$A14,"") -> EC_IE_010 | GS14: =IF(LEN(Folders!$A14)>0,Folders!$A14,"") | GT14: =IF(LEN(CustomFunctions!$A14)>0,CustomFunctions!$A14,"") | GU14: =IF(LEN(Fields!$G14)>0,Fields!$G14,"") -> SEX | GV14: =IF(LEN(Fields!$B14)>0,Fields!$B14,"") -> SEX
A15: DYN_DM_CBRSN | B15: 5 | D15: 5 | E15: $1 | Q15: LengthIsLessThan | GR15: =IF(LEN(Checks!$A15)>0,Checks!$A15,"") -> EC_IE_020 | GS15: =IF(LEN(Folders!$A15)>0,Folders!$A15,"") | GT15: =IF(LEN(CustomFunctions!$A15)>0,CustomFunctions!$A15,"") | GU15: =IF(LEN(Fields!$G15)>0,Fields!$G15,"") -> CBPYN | GV15: =IF(LEN(Fields!$B15)>0,Fields!$B15,"") -> CBPYN
A16: DYN_DM_CBRSN | B16: 6 | C16: IsEqualTo | Q16: LengthIsLessThanOrEqualTo | GR16: =IF(LEN(Checks!$A16)>0,Checks!$A16,"") -> EC_DM_010 | GS16: =IF(LEN(Folders!$A16)>0,Folders!$A16,"") | GT16: =IF(LEN(CustomFunctions!$A16)>0,CustomFunctions!$A16,"") | GU16: =IF(LEN(Fields!$G16)>0,Fields!$G16,"") -> CBRSN | GV16: =IF(LEN(Fields!$B16)>0,Fields!$B16,"") -> CBRSN
A17: DYN_DM_CBRSN | B17: 7 | C17: And | Q17: LengthIsGreaterThan | GR17: =IF(LEN(Checks!$A17)>0,Checks!$A17,"") | GS17: =IF(LEN(Folders!$A17)>0,Folders!$A17,"") | GT17: =IF(LEN(CustomFunctions!$A17)>0,CustomFunctions!$A17,"") | GU17: =IF(LEN(Fields!$G17)>0,Fields!$G17,"") -> CBRSN1DAT | GV17: =IF(LEN(Fields!$B17)>0,Fields!$B17,"") -> CBRSN1DAT
A18: DYN_DM_CBPYN | B18: 1 | E18: CodedValue | F18: CBPYN | H18: DM | I18: CBPYN | J18: 0 | Q18: LengthIsGreaterThanOrEqualTo | GR18: =IF(LEN(Checks!$A18)>0,Checks!$A18,"") | GS18: =IF(LEN(Folders!$A18)>0,Folders!$A18,"") | GT18: =IF(LEN(CustomFunctions!$A18)>0,CustomFunctions!$A18,"") | GU18: =IF(LEN(Fields!$G18)>0,Fields!$G18,"") -> CBRSNOTH | GV18: =IF(LEN(Fields!$B18)>0,Fields!$B18,"") -> CBRSNOTH
A19: DYN_DM_CBPYN | B19: 2 | D19: N | E19: $1 | Q19: LengthIsEqualTo | GR19: =IF(LEN(Checks!$A19)>0,Checks!$A19,"") | GS19: =IF(LEN(Folders!$A19)>0,Folders!$A19,"") | GT19: =IF(LEN(CustomFunctions!$A19)>0,CustomFunctions!$A19,"") | GU19: =IF(LEN(Fields!$G19)>0,Fields!$G19,"") -> ETHNIC | GV19: =IF(LEN(Fields!$B19)>0,Fields!$B19,"") -> ETHNIC
A20: DYN_DM_CBPYN | B20: 3 | C20: IsEqualTo | Q20: Or | GR20: =IF(LEN(Checks!$A20)>0,Checks!$A20,"") | GS20: =IF(LEN(Folders!$A20)>0,Folders!$A20,"") | GT20: =IF(LEN(CustomFunctions!$A20)>0,CustomFunctions!$A20,"") | GU20: =IF(LEN(Fields!$G20)>0,Fields!$G20,"") -> RACE | GV20: =IF(LEN(Fields!$B20)>0,Fields!$B20,"") -> RACE
A21: DYN_DM_SEX | B21: 1 | E21: CodedValue | F21: SEX | H21: DM | I21: SEX | J21: 0 | Q21: And | GR21: =IF(LEN(Checks!$A21)>0,Checks!$A21,"") | GS21: =IF(LEN(Folders!$A21)>0,Folders!$A21,"") | GT21: =IF(LEN(CustomFunctions!$A21)>0,CustomFunctions!$A21,"") | GU21: =IF(LEN(Fields!$G21)>0,Fields!$G21,"") -> RACEOTH | GV21: =IF(LEN(Fields!$B21)>0,Fields!$B21,"") -> RACEOTH
A22: DYN_DM_SEX | B22: 2 | D22: F | E22: $1 | Q22: Not | GR22: =IF(LEN(Checks!$A22)>0,Checks!$A22,"") | GS22: =IF(LEN(Folders!$A22)>0,Folders!$A22,"") | GT22: =IF(LEN(CustomFunctions!$A22)>0,CustomFunctions!$A22,"") | GU22: =IF(LEN(Fields!$G22)>0,Fields!$G22,"") -> DSCONTYN | GV22: =IF(LEN(Fields!$B22)>0,Fields!$B22,"") -> DSCONTYN
A23: DYN_DM_SEX | B23: 3 | C23: IsEqualTo | Q23: Now | GR23: =IF(LEN(Checks!$A23)>0,Checks!$A23,"") | GS23: =IF(LEN(Folders!$A23)>0,Folders!$A23,"") | GT23: =IF(LEN(CustomFunctions!$A23)>0,CustomFunctions!$A23,"") | GU23: =IF(LEN(Fields!$G23)>0,Fields!$G23,"") -> IEYN | GV23: =IF(LEN(Fields!$B23)>0,Fields!$B23,"") -> IEYN
A24: DYN_DM_RACE | B24: 1 | E24: CodedValue | F24: RACE | H24: DM | I24: RACE | J24: 0 | Q24: IsPresent | GR24: =IF(LEN(Checks!$A24)>0,Checks!$A24,"") | GS24: =IF(LEN(Folders!$A24)>0,Folders!$A24,"") | GT24: =IF(LEN(CustomFunctions!$A24)>0,CustomFunctions!$A24,"") | GU24: =IF(LEN(Fields!$G24)>0,Fields!$G24,"") | GV24: =IF(LEN(Fields!$B24)>0,Fields!$B24,"") -> IE_HEADER
A25: DYN_DM_RACE | B25: 2 | D25: OTHER | E25: $6 | Q25: IsActive | GR25: =IF(LEN(Checks!$A25)>0,Checks!$A25,"") | GS25: =IF(LEN(Folders!$A25)>0,Folders!$A25,"") | GT25: =IF(LEN(CustomFunctions!$A25)>0,CustomFunctions!$A25,"") | GU25: =IF(LEN(Fields!$G25)>0,Fields!$G25,"") -> IETESTCD | GV25: =IF(LEN(Fields!$B25)>0,Fields!$B25,"") -> IETESTCD
A26: DYN_DM_RACE | B26: 3 | C26: IsEqualTo | Q26: Add | GR26: =IF(LEN(Checks!$A26)>0,Checks!$A26,"") | GS26: =IF(LEN(Folders!$A26)>0,Folders!$A26,"") | GT26: =IF(LEN(CustomFunctions!$A26)>0,CustomFunctions!$A26,"") | GU26: =IF(LEN(Fields!$G26)>0,Fields!$G26,"") | GV26: =IF(LEN(Fields!$B26)>0,Fields!$B26,"")
A27: DYN_DM_CBRSN1DAT | B27: 1 | E27: CodedValue | F27: CBRSN | H27: DM | I27: CBRSN | J27: 0 | Q27: Subtract | GR27: =IF(LEN(Checks!$A27)>0,Checks!$A27,"") | GS27: =IF(LEN(Folders!$A27)>0,Folders!$A27,"") | GT27: =IF(LEN(CustomFunctions!$A27)>0,CustomFunctions!$A27,"") | GU27: =IF(LEN(Fields!$G27)>0,Fields!$G27,"") | GV27: =IF(LEN(Fields!$B27)>0,Fields!$B27,"")
A28: DYN_DM_CBRSN1DAT | B28: 2 | D28: 3 | E28: $1 | Q28: Multiply | GR28: =IF(LEN(Checks!$A28)>0,Checks!$A28,"") | GS28: =IF(LEN(Folders!$A28)>0,Folders!$A28,"") | GT28: =IF(LEN(CustomFunctions!$A28)>0,CustomFunctions!$A28,"") | GU28: =IF(LEN(Fields!$G28)>0,Fields!$G28,"") | GV28: =IF(LEN(Fields!$B28)>0,Fields!$B28,"")
A29: DYN_DM_CBRSN1DAT | B29: 3 | C29: IsEqualTo | Q29: Divide | GR29: =IF(LEN(Checks!$A29)>0,Checks!$A29,"") | GS29: =IF(LEN(Folders!$A29)>0,Folders!$A29,"") | GT29: =IF(LEN(CustomFunctions!$A29)>0,CustomFunctions!$A29,"") | GU29: =IF(LEN(Fields!$G29)>0,Fields!$G29,"") | GV29: =IF(LEN(Fields!$B29)>0,Fields!$B29,"")
A30: DYN_DM_CBRSN1DAT | B30: 4 | E30: CodedValue | F30: CBRSN | H30: DM | I30: CBRSN | J30: 0 | Q30: AddDay | GR30: =IF(LEN(Checks!$A30)>0,Checks!$A30,"") | GS30: =IF(LEN(Folders!$A30)>0,Folders!$A30,"") | GT30: =IF(LEN(CustomFunctions!$A30)>0,CustomFunctions!$A30,"") | GU30: =IF(LEN(Fields!$G30)>0,Fields!$G30,"") | GV30: =IF(LEN(Fields!$B30)>0,Fields!$B30,"")
A31: DYN_DM_CBRSN1DAT | B31: 5 | D31: 4 | E31: $1 | Q31: AddMonth | GR31: =IF(LEN(Checks!$A31)>0,Checks!$A31,"") | GS31: =IF(LEN(Folders!$A31)>0,Folders!$A31,"") | GT31: =IF(LEN(CustomFunctions!$A31)>0,CustomFunctions!$A31,"") | GU31: =IF(LEN(Fields!$G31)>0,Fields!$G31,"") | GV31: =IF(LEN(Fields!$B31)>0,Fields!$B31,"")
A32: DYN_DM_CBRSN1DAT | B32: 6 | C32: IsEqualTo | Q32: AddYear | GR32: =IF(LEN(Checks!$A32)>0,Checks!$A32,"") | GS32: =IF(LEN(Folders!$A32)>0,Folders!$A32,"") | GT32: =IF(LEN(CustomFunctions!$A32)>0,CustomFunctions!$A32,"") | GU32: =IF(LEN(Fields!$G32)>0,Fields!$G32,"") | GV32: =IF(LEN(Fields!$B32)>0,Fields!$B32,"")
A33: DYN_DM_CBRSN1DAT | B33: 7 | C33: Or | Q33: AddSec | GR33: =IF(LEN(Checks!$A33)>0,Checks!$A33,"") | GS33: =IF(LEN(Folders!$A33)>0,Folders!$A33,"") | GT33: =IF(LEN(CustomFunctions!$A33)>0,CustomFunctions!$A33,"") | GU33: =IF(LEN(Fields!$G33)>0,Fields!$G33,"") | GV33: =IF(LEN(Fields!$B33)>0,Fields!$B33,"")
A34: EC_SV_010 | B34: 1 | E34: StandardValue | F34: SVDAT | H34: SV | I34: SVDAT | J34: 0 | Q34: AddMin | GR34: =IF(LEN(Checks!$A34)>0,Checks!$A34,"") | GS34: =IF(LEN(Folders!$A34)>0,Folders!$A34,"") | GT34: =IF(LEN(CustomFunctions!$A34)>0,CustomFunctions!$A34,"") | GU34: =IF(LEN(Fields!$G34)>0,Fields!$G34,"") | GV34: =IF(LEN(Fields!$B34)>0,Fields!$B34,"")
A35: EC_SV_010 | B35: 2 | C35: IsNotEmpty | Q35: AddHour | GR35: =IF(LEN(Checks!$A35)>0,Checks!$A35,"") | GS35: =IF(LEN(Folders!$A35)>0,Folders!$A35,"") | GT35: =IF(LEN(CustomFunctions!$A35)>0,CustomFunctions!$A35,"") | GU35: =IF(LEN(Fields!$G35)>0,Fields!$G35,"") | GV35: =IF(LEN(Fields!$B35)>0,Fields!$B35,"")
A36: EC_SV_010 | B36: 3 | E36: StandardValue | F36: RFICDAT | G36: SCRN | H36: IC | I36: RFICDAT | J36: 0 | Q36: DaySpan | GR36: =IF(LEN(Checks!$A36)>0,Checks!$A36,"") | GS36: =IF(LEN(Folders!$A36)>0,Folders!$A36,"") | GT36: =IF(LEN(CustomFunctions!$A36)>0,CustomFunctions!$A36,"") | GU36: =IF(LEN(Fields!$G36)>0,Fields!$G36,"") | GV36: =IF(LEN(Fields!$B36)>0,Fields!$B36,"")
A37: EC_SV_010 | B37: 4 | C37: IsNotEmpty | Q37: TimeSpan | GR37: =IF(LEN(Checks!$A37)>0,Checks!$A37,"") | GS37: =IF(LEN(Folders!$A37)>0,Folders!$A37,"") | GT37: =IF(LEN(CustomFunctions!$A37)>0,CustomFunctions!$A37,"") | GU37: =IF(LEN(Fields!$G37)>0,Fields!$G37,"") | GV37: =IF(LEN(Fields!$B37)>0,Fields!$B37,"")
A38: EC_SV_010 | B38: 5 | C38: And | Q38: Age | GR38: =IF(LEN(Checks!$A38)>0,Checks!$A38,"") | GS38: =IF(LEN(Folders!$A38)>0,Folders!$A38,"") | GT38: =IF(LEN(CustomFunctions!$A38)>0,CustomFunctions!$A38,"") | GU38: =IF(LEN(Fields!$G38)>0,Fields!$G38,"") | GV38: =IF(LEN(Fields!$B38)>0,Fields!$B38,"")
A39: EC_SV_010 | B39: 6 | E39: StandardValue | F39: SVDAT | H39: SV | I39: SVDAT | J39: 0 | Q39: StringAdd | GR39: =IF(LEN(Checks!$A39)>0,Checks!$A39,"") | GS39: =IF(LEN(Folders!$A39)>0,Folders!$A39,"") | GT39: =IF(LEN(CustomFunctions!$A39)>0,CustomFunctions!$A39,"") | GU39: =IF(LEN(Fields!$G39)>0,Fields!$G39,"") | GV39: =IF(LEN(Fields!$B39)>0,Fields!$B39,"")
A40: EC_SV_010 | B40: 7 | E40: StandardValue | F40: RFICDAT | G40: SCRN | H40: IC | I40: RFICDAT | J40: 0 | GR40: =IF(LEN(Checks!$A40)>0,Checks!$A40,"") | GS40: =IF(LEN(Folders!$A40)>0,Folders!$A40,"") | GT40: =IF(LEN(CustomFunctions!$A40)>0,CustomFunctions!$A40,"") | GU40: =IF(LEN(Fields!$G40)>0,Fields!$G40,"") | GV40: =IF(LEN(Fields!$B40)>0,Fields!$B40,"")
...

Sheet CheckActions
A1: CheckName | B1: FolderOID | C1: FormOID | D1: FieldOID | E1: VariableOID | F1: RecordPosition | G1: PageRepeatNumber | H1: InstanceRepeatNumber | I1: LogicalRecordPosition | J1: Scope | K1: OrderBy | L1: ActionType | M1: ActionString | N1: ActionHeader | O1: ActionOptions | P1: TargetID | Q1: ActionScript | R1: ActionType_ValCol
A2: DYN_SV_SVOCCUR_N | C2: SV | D2: SVOCCUR | E2: SVOCCUR | F2: 0 | L2: IsPresent | O2: 0 | P2: 0 | R2: UpdateFolderName | GR2: =IF(LEN(Forms!$A2)>0,Forms!$A2,"") -> SUBJECT | GS2: =IF(LEN(Checks!$A2)>0,Checks!$A2,"") -> DYN_SV_SVOCCUR_N | GT2: =IF(LEN(Folders!$A2)>0,Folders!$A2,"") -> SCRN | GU2: =IF(LEN(Fields!$B2)>0,Fields!$B2,"") -> SUB_HEADER | GV2: =IF(LEN(Fields!$G2)>0,Fields!$G2,"")
A3: DYN_SV_SVOCCUR_N | C3: SV | D3: SVREASND | E3: SVREASND | F3: 0 | L3: SetDataPointVisible | O3: TRUE (Enter Empty When Not Visible) | P3: 0 | R3: UpdateFormName | GR3: =IF(LEN(Forms!$A3)>0,Forms!$A3,"") -> SV | GS3: =IF(LEN(Checks!$A3)>0,Checks!$A3,"") -> DYN_SV_SVOCCUR_Y | GT3: =IF(LEN(Folders!$A3)>0,Folders!$A3,"") -> BASE | GU3: =IF(LEN(Fields!$B3)>0,Fields!$B3,"") -> SUBJID | GV3: =IF(LEN(Fields!$G3)>0,Fields!$G3,"") -> SUBJID
A4: DYN_SV_SVOCCUR_Y | C4: SV | D4: SVOCCUR | E4: SVOCCUR | F4: 0 | L4: IsPresent | O4: 0 | P4: 0 | R4: OpenQuery | GR4: =IF(LEN(Forms!$A4)>0,Forms!$A4,"") -> IC | GS4: =IF(LEN(Checks!$A4)>0,Checks!$A4,"") -> DYN_IC_ICYN | GT4: =IF(LEN(Folders!$A4)>0,Folders!$A4,"") | GU4: =IF(LEN(Fields!$B4)>0,Fields!$B4,"") -> SUBMDTM | GV4: =IF(LEN(Fields!$G4)>0,Fields!$G4,"") -> SUBMDTM
A5: DYN_SV_SVOCCUR_Y | C5: SV | D5: SVDAT | E5: SVDAT | F5: 0 | L5: SetDataPointVisible | O5: TRUE (Enter Empty When Not Visible) | P5: 0 | R5: RequireReview | GR5: =IF(LEN(Forms!$A5)>0,Forms!$A5,"") -> DM | GS5: =IF(LEN(Checks!$A5)>0,Checks!$A5,"") -> DYN_DM_CBRSN | GT5: =IF(LEN(Folders!$A5)>0,Folders!$A5,"") | GU5: =IF(LEN(Fields!$B5)>0,Fields!$B5,"") -> SVOCCUR | GV5: =IF(LEN(Fields!$G5)>0,Fields!$G5,"") -> SVOCCUR
A6: DYN_IC_ICYN | C6: IC | D6: ICYN | E6: ICYN | F6: 0 | L6: IsPresent | O6: 0 | P6: 0 | R6: RequireVerification | GR6: =IF(LEN(Forms!$A6)>0,Forms!$A6,"") -> CONTD | GS6: =IF(LEN(Checks!$A6)>0,Checks!$A6,"") -> DYN_DM_CBPYN | GT6: =IF(LEN(Folders!$A6)>0,Folders!$A6,"") | GU6: =IF(LEN(Fields!$B6)>0,Fields!$B6,"") -> SVREASND | GV6: =IF(LEN(Fields!$G6)>0,Fields!$G6,"") -> SVREASND
A7: DYN_IC_ICYN | C7: IC | D7: RFICDAT | E7: RFICDAT | F7: 0 | L7: SetDataPointVisible | O7: TRUE (Enter Empty When Not Visible) | P7: 0 | R7: AddComment | GR7: =IF(LEN(Forms!$A7)>0,Forms!$A7,"") -> IE | GS7: =IF(LEN(Checks!$A7)>0,Checks!$A7,"") -> DYN_DM_SEX | GT7: =IF(LEN(Folders!$A7)>0,Folders!$A7,"") | GU7: =IF(LEN(Fields!$B7)>0,Fields!$B7,"") -> SVDAT | GV7: =IF(LEN(Fields!$G7)>0,Fields!$G7,"") -> SVDAT
A8: DYN_IC_ICYN | C8: IC | D8: ICTIM | E8: ICTIM | F8: 0 | L8: SetDataPointVisible | O8: TRUE (Enter Empty When Not Visible) | P8: 0 | R8: AddDeviation | GR8: =IF(LEN(Forms!$A8)>0,Forms!$A8,"") | GS8: =IF(LEN(Checks!$A8)>0,Checks!$A8,"") -> DYN_DM_RACE | GT8: =IF(LEN(Folders!$A8)>0,Folders!$A8,"") | GU8: =IF(LEN(Fields!$B8)>0,Fields!$B8,"") -> ICYN | GV8: =IF(LEN(Fields!$G8)>0,Fields!$G8,"") -> ICYN
A9: DYN_IC_ICYN | C9: IC | D9: ICPROT | E9: ICPROT | F9: 0 | L9: SetDataPointVisible | O9: TRUE (Enter Empty When Not Visible) | P9: 0 | R9: CustomFunction | GR9: =IF(LEN(Forms!$A9)>0,Forms!$A9,"") | GS9: =IF(LEN(Checks!$A9)>0,Checks!$A9,"") -> DYN_DM_CBRSN1DAT | GT9: =IF(LEN(Folders!$A9)>0,Folders!$A9,"") | GU9: =IF(LEN(Fields!$B9)>0,Fields!$B9,"") -> RFICDAT | GV9: =IF(LEN(Fields!$G9)>0,Fields!$G9,"") -> RFICDAT
A10: DYN_DM_CBRSN | C10: DM | D10: CBRSNOTH | E10: CBRSNOTH | F10: 0 | L10: SetDataPointVisible | O10: TRUE (Enter Empty When Not Visible) | P10: 0 | R10: PlaceSticky | GR10: =IF(LEN(Forms!$A10)>0,Forms!$A10,"") | GS10: =IF(LEN(Checks!$A10)>0,Checks!$A10,"") -> EC_SV_010 | GT10: =IF(LEN(Folders!$A10)>0,Folders!$A10,"") | GU10: =IF(LEN(Fields!$B10)>0,Fields!$B10,"") -> ICTIM | GV10: =IF(LEN(Fields!$G10)>0,Fields!$G10,"") -> ICTIM
A11: DYN_DM_CBRSN | C11: DM | D11: CBPYN | E11: CBPYN | F11: 0 | L11: IsPresent | O11: 0 | P11: 0 | R11: AddForm | GR11: =IF(LEN(Forms!$A11)>0,Forms!$A11,"") | GS11: =IF(LEN(Checks!$A11)>0,Checks!$A11,"") -> D_CF_SUBJID_01 | GT11: =IF(LEN(Folders!$A11)>0,Folders!$A11,"") | GU11: =IF(LEN(Fields!$B11)>0,Fields!$B11,"") -> ICPROT | GV11: =IF(LEN(Fields!$G11)>0,Fields!$G11,"") -> ICPROT
A12: DYN_DM_CBPYN | C12: DM | D12: CBRSN | E12: CBRSN | F12: 0 | L12: SetDataPointVisible | O12: TRUE (Enter Empty When Not Visible) | P12: 0 | R12: AddMatrix | GR12: =IF(LEN(Forms!$A12)>0,Forms!$A12,"") | GS12: =IF(LEN(Checks!$A12)>0,Checks!$A12,"") -> MERGE_SCRN | GT12: =IF(LEN(Folders!$A12)>0,Folders!$A12,"") | GU12: =IF(LEN(Fields!$B12)>0,Fields!$B12,"") -> BRTHDAT | GV12: =IF(LEN(Fields!$G12)>0,Fields!$G12,"") -> BRTHDAT
A13: DYN_DM_CBPYN | C13: DM | D13: CBPYN | E13: CBPYN | F13: 0 | L13: IsPresent | O13: 0 | P13: 0 | R13: MrgMatrix | GR13: =IF(LEN(Forms!$A13)>0,Forms!$A13,"") | GS13: =IF(LEN(Checks!$A13)>0,Checks!$A13,"") -> MERGE_BASE_SV | GT13: =IF(LEN(Folders!$A13)>0,Folders!$A13,"") | GU13: =IF(LEN(Fields!$B13)>0,Fields!$B13,"") -> AGE | GV13: =IF(LEN(Fields!$G13)>0,Fields!$G13,"") -> AGE
... A19: DYN_DM_CBRSN1DAT | C19: DM | D19: CBRSN1DAT | E19: CBRSN1DAT | F19: 0 | L19: SetDataPointVisible | O19: TRUE (Enter Empty When Not Visible) | P19: 0 | R19: SetTimeForward | GR19: =IF(LEN(Forms!$A19)>0,Forms!$A19,"") | GS19: =IF(LEN(Checks!$A19)>0,Checks!$A19,"") | GT19: =IF(LEN(Folders!$A19)>0,Folders!$A19,"") | GU19: =IF(LEN(Fields!$B19)>0,Fields!$B19,"") -> ETHNIC | GV19: =IF(LEN(Fields!$G19)>0,Fields!$G19,"") -> ETHNIC
A20: EC_SV_010 | C20: SV | D20: SVDAT | E20: SVDAT | F20: 0 | L20: OpenQuery | M20: Visit Date is prior to the Date of Informed Consent. Please review and update, else clarify. | O20: Site from System,RequiresResponse,RequiresManualClose | P20: 0 | R20: SetSubjectStatus | GR20: =IF(LEN(Forms!$A20)>0,Forms!$A20,"") | GS20: =IF(LEN(Checks!$A20)>0,Checks!$A20,"") | GT20: =IF(LEN(Folders!$A20)>0,Folders!$A20,"") | GU20: =IF(LEN(Fields!$B20)>0,Fields!$B20,"") -> RACE | GV20: =IF(LEN(Fields!$G20)>0,Fields!$G20,"") -> RACE
A21: D_CF_SUBJID_01 | C21: SUBJECT | D21: SUBMDTM | E21: SUBMDTM | F21: 0 | L21: CustomFunction | O21: CF_SUBJECT_01 | P21: 0 | R21: SetSubjectName | GR21: =IF(LEN(Forms!$A21)>0,Forms!$A21,"") | GS21: =IF(LEN(Checks!$A21)>0,Checks!$A21,"") | GT21: =IF(LEN(Folders!$A21)>0,Folders!$A21,"") | GU21: =IF(LEN(Fields!$B21)>0,Fields!$B21,"") -> RACEOTH | GV21: =IF(LEN(Fields!$G21)>0,Fields!$G21,"") -> RACEOTH
A22: MERGE_SCRN | B22: SCRN | C22: IE | D22: IEYN | E22: IEYN | F22: 0 | L22: MrgMatrix | O22: SCRN | P22: 0 | R22: SetRecordDate | GR22: =IF(LEN(Forms!$A22)>0,Forms!$A22,"") | GS22: =IF(LEN(Checks!$A22)>0,Checks!$A22,"") | GT22: =IF(LEN(Folders!$A22)>0,Folders!$A22,"") | GU22: =IF(LEN(Fields!$B22)>0,Fields!$B22,"") -> DSCONTYN | GV22: =IF(LEN(Fields!$G22)>0,Fields!$G22,"") -> DSCONTYN
A23: MERGE_BASE_SV | B23: SCRN | C23: IE | D23: IEYN | E23: IEYN | F23: 0 | L23: MrgMatrix | O23: BASE_SV | P23: 0 | R23: SetDataPageDate | GR23: =IF(LEN(Forms!$A23)>0,Forms!$A23,"") | GS23: =IF(LEN(Checks!$A23)>0,Checks!$A23,"") | GT23: =IF(LEN(Folders!$A23)>0,Folders!$A23,"") | GU23: =IF(LEN(Fields!$B23)>0,Fields!$B23,"") -> IEYN | GV23: =IF(LEN(Fields!$G23)>0,Fields!$G23,"") -> IEYN
A24: EC_IE_010 | C24: IE | D24: IEYN | E24: IEYN | F24: 0 | L24: OpenQuery | M24: Response to 'Is Subject eligible for this Study?' is 'No'; however, response to 'Criterion Identifier' is missing. Please review and update, else clarify. | O24: Site from System,RequiresResponse,RequiresManualClose | P24: 0 | R24: SetInstanceDate | GR24: =IF(LEN(Forms!$A24)>0,Forms!$A24,"") | GS24: =IF(LEN(Checks!$A24)>0,Checks!$A24,"") | GT24: =IF(LEN(Folders!$A24)>0,Folders!$A24,"") | GU24: =IF(LEN(Fields!$B24)>0,Fields!$B24,"") -> IE_HEADER | GV24: =IF(LEN(Fields!$G24)>0,Fields!$G24,"")
